<?xml version="1.0" encoding="utf-8"?>
<!-- =================================================================================== -->
<!-- |    This document was autogenerated by xacro from hexapod.xacro                  | -->
<!-- |    EDITING THIS FILE BY HAND IS NOT RECOMMENDED                                 | -->
<!-- =================================================================================== -->
<robot name="hexapod">
  <gazebo>
    <plugin filename="libgazebo_ros_control.so" name="gazebo_ros_control">
      <robotNamespace>/hexapod</robotNamespace>
    </plugin>
  </gazebo>
  <gazebo>
    <plugin filename="libgazebo_ros_p3d.so" name="p3d_base_controller">
      <alwaysOn>true</alwaysOn>
      <updateRate>30.0</updateRate>
      <bodyName>base</bodyName>
      <topicName>odom</topicName>
      <gaussianNoise>0</gaussianNoise>
      <frameName>world</frameName>
      <xyzOffsets>0 0 0</xyzOffsets>
      <rpyOffsets>0 0 0</rpyOffsets>
    </plugin>
  </gazebo>
  <link name="base"/>
  <joint name="base_to_hexapod_joint" type="fixed">
    <parent link="base"/>
    <child link="hexapod_link"/>
  </joint>
  <link name="hexapod_link">
    <visual>
      <geometry>
        <mesh filename="package://hexapod/stl/hexapod_link.stl"/>
      </geometry>
      <origin rpy="0 0 0" xyz="0 0 0"/>
      <material name="grey">
        <color rgba="0.67 0.67 0.67 1"/>
      </material>
    </visual>
    <inertial>
      <mass value="0.2"/>
      <inertia ixx="0.006783591" ixy="0" ixz="-9.71292E-07" iyy="0.000361804" iyz="-1.57895E-05" izz="0.007021976"/>
    </inertial>
    <collision>
      <geometry>
        <mesh filename="package://hexapod/stl/hexapod_link.stl"/>
      </geometry>
      <origin rpy="0 0 0" xyz="0 0 0"/>
    </collision>
  </link>
  <link name="1_coxa_link">
    <visual>
      <geometry>
        <mesh filename="package://hexapod/stl/coxa_l_link.stl"/>
      </geometry>
      <origin rpy="0 0 0" xyz="0 0 0"/>
      <material name="grey">
        <color rgba="0.67 0.67 0.67 1"/>
      </material>
    </visual>
    <inertial>
      <mass value="0.2"/>
      <inertia ixx="4.99231E-05" ixy="7.69231E-08" ixz="0" iyy="4.83846E-05" iyz="0" izz="4.83846E-05"/>
    </inertial>
    <collision>
      <geometry>
        <mesh filename="package://hexapod/stl/coxa_l_link.stl"/>
      </geometry>
      <origin rpy="0 0 0" xyz="0 0 0"/>
    </collision>
  </link>
  <joint name="m11" type="revolute">
    <parent link="hexapod_link"/>
    <child link="1_coxa_link"/>
    <origin rpy="0 0 2.791" xyz="-0.051 0.217 0.0"/>
    <axis xyz="0 0 1"/>
    <limit effort="1000.0" lower="-3.14" upper="3.14" velocity="0.5"/>
    <!--lower="-0.548" upper="0.548" -->
  </joint>
  <link name="1_femur_link">
    <visual>
      <geometry>
        <mesh filename="package://hexapod/stl/femur_link.stl"/>
      </geometry>
      <origin rpy="0 0 0" xyz="0 0 0"/>
      <material name="grey">
        <color rgba="0.67 0.67 0.67 1"/>
      </material>
    </visual>
    <inertial>
      <mass value="0.2"/>
      <inertia ixx="2.40946E-05" ixy="-1.00676E-06" ixz="-7.43243E-07" iyy="0.000142824" iyz="-6.75676E-09" izz="0.000150466"/>
    </inertial>
    <collision>
      <geometry>
        <mesh filename="package://hexapod/stl/femur_link.stl"/>
      </geometry>
      <origin rpy="0 0 0" xyz="0 0 0"/>
    </collision>
  </link>
  <joint name="m12" type="revolute">
    <parent link="1_coxa_link"/>
    <child link="1_femur_link"/>
    <origin rpy="3.14 0 0" xyz="0.07 0.0 0.0"/>
    <axis xyz="0 1 0"/>
    <limit effort="1000.0" lower="-3.14" upper="3.14" velocity="0.5"/>
    <!-- lower="-1.57" upper="1.57" -->
  </joint>
  <link name="1_tibia_link">
    <visual>
      <geometry>
        <mesh filename="package://hexapod/stl/tibia_link.stl"/>
      </geometry>
      <origin rpy="0 0 0" xyz="0 0 0"/>
      <material name="grey">
        <color rgba="0.67 0.67 0.67 1"/>
      </material>
    </visual>
    <inertial>
      <mass value="0.2"/>
      <inertia ixx="0.000296304" ixy="-4.34783E-08" ixz="3.26087E-06" iyy="0.000265391" iyz="1.73913E-06" izz="4.22174E-05"/>
    </inertial>
    <collision>
      <geometry>
        <mesh filename="package://hexapod/stl/tibia_link.stl"/>
      </geometry>
      <origin rpy="0 0 0" xyz="0 0 0"/>
    </collision>
  </link>
  <joint name="m13" type="revolute">
    <parent link="1_femur_link"/>
    <child link="1_tibia_link"/>
    <origin rpy="0 -1.57 0" xyz="0.096 0.0 0.0"/>
    <axis xyz="0 1 0"/>
    <limit effort="1000.0" lower="-3.14" upper="3.14" velocity="0.5"/>
    <!-- lower="-1.57" upper="1.57" -->
  </joint>
  <link name="1_foot_link"/>
  <joint name="1_foot_joint" type="fixed">
    <parent link="1_tibia_link"/>
    <child link="1_foot_link"/>
    <origin rpy="0.0 0.0 0.0" xyz="0 0.0 -0.162"/>
    <axis xyz="0 1 0"/>
  </joint>
  <transmission name="m11_trans">
    <type>transmission_interface/SimpleTransmission</type>
    <joint name="m11">
      <hardwareInterface>hardware_interface/EffortJointInterface</hardwareInterface>
    </joint>
    <actuator name="m11_motor">
      <hardwareInterface>hardware_interface/EffortJointInterface</hardwareInterface>
      <mechanicalReduction>1</mechanicalReduction>
    </actuator>
  </transmission>
  <transmission name="m12_trans">
    <type>transmission_interface/SimpleTransmission</type>
    <joint name="m12">
      <hardwareInterface>hardware_interface/EffortJointInterface</hardwareInterface>
    </joint>
    <actuator name="m12_motor">
      <hardwareInterface>hardware_interface/EffortJointInterface</hardwareInterface>
      <mechanicalReduction>1</mechanicalReduction>
    </actuator>
  </transmission>
  <transmission name="m13_trans">
    <type>transmission_interface/SimpleTransmission</type>
    <joint name="m13">
      <hardwareInterface>hardware_interface/EffortJointInterface</hardwareInterface>
    </joint>
    <actuator name="m13_motor">
      <hardwareInterface>hardware_interface/EffortJointInterface</hardwareInterface>
      <mechanicalReduction>1</mechanicalReduction>
    </actuator>
  </transmission>
  <link name="2_coxa_link">
    <visual>
      <geometry>
        <mesh filename="package://hexapod/stl/coxa_r_link.stl"/>
      </geometry>
      <origin rpy="0 0 0" xyz="0 0 0"/>
      <material name="grey">
        <color rgba="0.67 0.67 0.67 1"/>
      </material>
    </visual>
    <inertial>
      <mass value="0.2"/>
      <inertia ixx="4.99231E-05" ixy="7.69231E-08" ixz="0" iyy="4.83846E-05" iyz="0" izz="4.83846E-05"/>
    </inertial>
    <collision>
      <geometry>
        <mesh filename="package://hexapod/stl/coxa_r_link.stl"/>
      </geometry>
      <origin rpy="0 0 0" xyz="0 0 0"/>
    </collision>
  </link>
  <joint name="m21" type="revolute">
    <parent link="hexapod_link"/>
    <child link="2_coxa_link"/>
    <origin rpy="0 0 3.489" xyz="0.051 0.217 0.0"/>
    <axis xyz="0 0 1"/>
    <limit effort="1000.0" lower="-3.14" upper="3.14" velocity="0.5"/>
    <!-- lower="-0.548" upper="0.548" -->
  </joint>
  <link name="2_femur_link">
    <visual>
      <geometry>
        <mesh filename="package://hexapod/stl/femur_link.stl"/>
      </geometry>
      <origin rpy="0 0 0" xyz="0 0 0"/>
      <material name="grey">
        <color rgba="0.67 0.67 0.67 1"/>
      </material>
    </visual>
    <inertial>
      <mass value="0.2"/>
      <inertia ixx="2.40946E-05" ixy="-1.00676E-06" ixz="-7.43243E-07" iyy="0.000142824" iyz="-6.75676E-09" izz="0.000150466"/>
    </inertial>
    <collision>
      <geometry>
        <mesh filename="package://hexapod/stl/femur_link.stl"/>
      </geometry>
      <origin rpy="0 0 0" xyz="0 0 0"/>
    </collision>
  </link>
  <joint name="m22" type="revolute">
    <parent link="2_coxa_link"/>
    <child link="2_femur_link"/>
    <origin rpy="0 3.14 0" xyz="-0.07 0.0 0.0"/>
    <axis xyz="0 1 0"/>
    <limit effort="1000.0" lower="-3.14" upper="3.14" velocity="0.5"/>
    <!-- lower="-1.57" upper="1.57" -->
  </joint>
  <link name="2_tibia_link">
    <visual>
      <geometry>
        <mesh filename="package://hexapod/stl/tibia_link.stl"/>
      </geometry>
      <origin rpy="0 0 0" xyz="0 0 0"/>
      <material name="grey">
        <color rgba="0.67 0.67 0.67 1"/>
      </material>
    </visual>
    <inertial>
      <mass value="0.2"/>
      <inertia ixx="0.000296304" ixy="-4.34783E-08" ixz="3.26087E-06" iyy="0.000265391" iyz="1.73913E-06" izz="4.22174E-05"/>
    </inertial>
    <collision>
      <geometry>
        <mesh filename="package://hexapod/stl/tibia_link.stl"/>
      </geometry>
      <origin rpy="0 0 0" xyz="0 0 0"/>
    </collision>
  </link>
  <joint name="m23" type="revolute">
    <parent link="2_femur_link"/>
    <child link="2_tibia_link"/>
    <origin rpy="0 -1.57 0" xyz="0.096 0.0 0.0"/>
    <axis xyz="0 1 0"/>
    <limit effort="1000.0" lower="-3.14" upper="3.14" velocity="0.5"/>
    <!-- lower="-1.57" upper="1.57" -->
  </joint>
  <link name="2_foot_link"/>
  <joint name="2_foot_joint" type="fixed">
    <parent link="2_tibia_link"/>
    <child link="2_foot_link"/>
    <origin rpy="0.0 0.0 0.0" xyz="0 0.0 -0.162"/>
    <axis xyz="0 1 0"/>
  </joint>
  <transmission name="m21_trans">
    <type>transmission_interface/SimpleTransmission</type>
    <joint name="m21">
      <hardwareInterface>hardware_interface/EffortJointInterface</hardwareInterface>
    </joint>
    <actuator name="m21_motor">
      <hardwareInterface>hardware_interface/EffortJointInterface</hardwareInterface>
      <mechanicalReduction>1</mechanicalReduction>
    </actuator>
  </transmission>
  <transmission name="m22_trans">
    <type>transmission_interface/SimpleTransmission</type>
    <joint name="m22">
      <hardwareInterface>hardware_interface/EffortJointInterface</hardwareInterface>
    </joint>
    <actuator name="m22_motor">
      <hardwareInterface>hardware_interface/EffortJointInterface</hardwareInterface>
      <mechanicalReduction>1</mechanicalReduction>
    </actuator>
  </transmission>
  <transmission name="m23_trans">
    <type>transmission_interface/SimpleTransmission</type>
    <joint name="m23">
      <hardwareInterface>hardware_interface/EffortJointInterface</hardwareInterface>
    </joint>
    <actuator name="m23_motor">
      <hardwareInterface>hardware_interface/EffortJointInterface</hardwareInterface>
      <mechanicalReduction>1</mechanicalReduction>
    </actuator>
  </transmission>
  <link name="3_coxa_link">
    <visual>
      <geometry>
        <mesh filename="package://hexapod/stl/coxa_l_link.stl"/>
      </geometry>
      <origin rpy="0 0 0" xyz="0 0 0"/>
      <material name="grey">
        <color rgba="0.67 0.67 0.67 1"/>
      </material>
    </visual>
    <inertial>
      <mass value="0.2"/>
      <inertia ixx="4.99231E-05" ixy="7.69231E-08" ixz="0" iyy="4.83846E-05" iyz="0" izz="4.83846E-05"/>
    </inertial>
    <collision>
      <geometry>
        <mesh filename="package://hexapod/stl/coxa_l_link.stl"/>
      </geometry>
      <origin rpy="0 0 0" xyz="0 0 0"/>
    </collision>
  </link>
  <joint name="m31" type="revolute">
    <parent link="hexapod_link"/>
    <child link="3_coxa_link"/>
    <origin rpy="0 0 3.1415926" xyz="-0.051 0.0 0.0"/>
    <axis xyz="0 0 1"/>
    <limit effort="1000.0" lower="-0.548" upper="0.548" velocity="0.5"/>
  </joint>
  <link name="3_femur_link">
    <visual>
      <geometry>
        <mesh filename="package://hexapod/stl/femur_link.stl"/>
      </geometry>
      <origin rpy="0 0 0" xyz="0 0 0"/>
      <material name="grey">
        <color rgba="0.67 0.67 0.67 1"/>
      </material>
    </visual>
    <inertial>
      <mass value="0.2"/>
      <inertia ixx="2.40946E-05" ixy="-1.00676E-06" ixz="-7.43243E-07" iyy="0.000142824" iyz="-6.75676E-09" izz="0.000150466"/>
    </inertial>
    <collision>
      <geometry>
        <mesh filename="package://hexapod/stl/femur_link.stl"/>
      </geometry>
      <origin rpy="0 0 0" xyz="0 0 0"/>
    </collision>
  </link>
  <joint name="m32" type="revolute">
    <parent link="3_coxa_link"/>
    <child link="3_femur_link"/>
    <origin rpy="3.14 0 0" xyz="0.07 0.0 0.0"/>
    <axis xyz="0 1 0"/>
    <limit effort="1000.0" lower="-1.57" upper="1.57" velocity="0.5"/>
  </joint>
  <link name="3_tibia_link">
    <visual>
      <geometry>
        <mesh filename="package://hexapod/stl/tibia_link.stl"/>
      </geometry>
      <origin rpy="0 0 0" xyz="0 0 0"/>
      <material name="grey">
        <color rgba="0.67 0.67 0.67 1"/>
      </material>
    </visual>
    <inertial>
      <mass value="0.2"/>
      <inertia ixx="0.000296304" ixy="-4.34783E-08" ixz="3.26087E-06" iyy="0.000265391" iyz="1.73913E-06" izz="4.22174E-05"/>
    </inertial>
    <collision>
      <geometry>
        <mesh filename="package://hexapod/stl/tibia_link.stl"/>
      </geometry>
      <origin rpy="0 0 0" xyz="0 0 0"/>
    </collision>
  </link>
  <joint name="m33" type="revolute">
    <parent link="3_femur_link"/>
    <child link="3_tibia_link"/>
    <origin rpy="0 -1.57 0" xyz="0.096 0.0 0.0"/>
    <axis xyz="0 1 0"/>
    <limit effort="1000.0" lower="-1.57" upper="1.57" velocity="0.5"/>
  </joint>
  <link name="3_foot_link"/>
  <joint name="3_foot_joint" type="fixed">
    <parent link="3_tibia_link"/>
    <child link="3_foot_link"/>
    <origin rpy="0.0 0.0 0.0" xyz="0 0.0 -0.162"/>
    <axis xyz="0 1 0"/>
  </joint>
  <transmission name="m31_trans">
    <type>transmission_interface/SimpleTransmission</type>
    <joint name="m31">
      <hardwareInterface>hardware_interface/EffortJointInterface</hardwareInterface>
    </joint>
    <actuator name="m31_motor">
      <hardwareInterface>hardware_interface/EffortJointInterface</hardwareInterface>
      <mechanicalReduction>1</mechanicalReduction>
    </actuator>
  </transmission>
  <transmission name="m32_trans">
    <type>transmission_interface/SimpleTransmission</type>
    <joint name="m32">
      <hardwareInterface>hardware_interface/EffortJointInterface</hardwareInterface>
    </joint>
    <actuator name="m32_motor">
      <hardwareInterface>hardware_interface/EffortJointInterface</hardwareInterface>
      <mechanicalReduction>1</mechanicalReduction>
    </actuator>
  </transmission>
  <transmission name="m33_trans">
    <type>transmission_interface/SimpleTransmission</type>
    <joint name="m33">
      <hardwareInterface>hardware_interface/EffortJointInterface</hardwareInterface>
    </joint>
    <actuator name="m33_motor">
      <hardwareInterface>hardware_interface/EffortJointInterface</hardwareInterface>
      <mechanicalReduction>1</mechanicalReduction>
    </actuator>
  </transmission>
  <link name="4_coxa_link">
    <visual>
      <geometry>
        <mesh filename="package://hexapod/stl/coxa_r_link.stl"/>
      </geometry>
      <origin rpy="0 0 0" xyz="0 0 0"/>
      <material name="grey">
        <color rgba="0.67 0.67 0.67 1"/>
      </material>
    </visual>
    <inertial>
      <mass value="0.2"/>
      <inertia ixx="4.99231E-05" ixy="7.69231E-08" ixz="0" iyy="4.83846E-05" iyz="0" izz="4.83846E-05"/>
    </inertial>
    <collision>
      <geometry>
        <mesh filename="package://hexapod/stl/coxa_r_link.stl"/>
      </geometry>
      <origin rpy="0 0 0" xyz="0 0 0"/>
    </collision>
  </link>
  <joint name="m41" type="revolute">
    <parent link="hexapod_link"/>
    <child link="4_coxa_link"/>
    <origin rpy="0 0 3.1415926" xyz="0.051 0.0 0.0"/>
    <axis xyz="0 0 1"/>
    <limit effort="1000.0" lower="-0.548" upper="0.548" velocity="0.5"/>
  </joint>
  <link name="4_femur_link">
    <visual>
      <geometry>
        <mesh filename="package://hexapod/stl/femur_link.stl"/>
      </geometry>
      <origin rpy="0 0 0" xyz="0 0 0"/>
      <material name="grey">
        <color rgba="0.67 0.67 0.67 1"/>
      </material>
    </visual>
    <inertial>
      <mass value="0.2"/>
      <inertia ixx="2.40946E-05" ixy="-1.00676E-06" ixz="-7.43243E-07" iyy="0.000142824" iyz="-6.75676E-09" izz="0.000150466"/>
    </inertial>
    <collision>
      <geometry>
        <mesh filename="package://hexapod/stl/femur_link.stl"/>
      </geometry>
      <origin rpy="0 0 0" xyz="0 0 0"/>
    </collision>
  </link>
  <joint name="m42" type="revolute">
    <parent link="4_coxa_link"/>
    <child link="4_femur_link"/>
    <origin rpy="0 3.14 0" xyz="-0.07 0.0 0.0"/>
    <axis xyz="0 1 0"/>
    <limit effort="1000.0" lower="-1.57" upper="1.57" velocity="0.5"/>
  </joint>
  <link name="4_tibia_link">
    <visual>
      <geometry>
        <mesh filename="package://hexapod/stl/tibia_link.stl"/>
      </geometry>
      <origin rpy="0 0 0" xyz="0 0 0"/>
      <material name="grey">
        <color rgba="0.67 0.67 0.67 1"/>
      </material>
    </visual>
    <inertial>
      <mass value="0.2"/>
      <inertia ixx="0.000296304" ixy="-4.34783E-08" ixz="3.26087E-06" iyy="0.000265391" iyz="1.73913E-06" izz="4.22174E-05"/>
    </inertial>
    <collision>
      <geometry>
        <mesh filename="package://hexapod/stl/tibia_link.stl"/>
      </geometry>
      <origin rpy="0 0 0" xyz="0 0 0"/>
    </collision>
  </link>
  <joint name="m43" type="revolute">
    <parent link="4_femur_link"/>
    <child link="4_tibia_link"/>
    <origin rpy="0 -1.57 0" xyz="0.096 0.0 0.0"/>
    <axis xyz="0 1 0"/>
    <limit effort="1000.0" lower="-1.57" upper="1.57" velocity="0.5"/>
  </joint>
  <link name="4_foot_link"/>
  <joint name="4_foot_joint" type="fixed">
    <parent link="4_tibia_link"/>
    <child link="4_foot_link"/>
    <origin rpy="0.0 0.0 0.0" xyz="0 0.0 -0.162"/>
    <axis xyz="0 1 0"/>
  </joint>
  <transmission name="m41_trans">
    <type>transmission_interface/SimpleTransmission</type>
    <joint name="m41">
      <hardwareInterface>hardware_interface/EffortJointInterface</hardwareInterface>
    </joint>
    <actuator name="m41_motor">
      <hardwareInterface>hardware_interface/EffortJointInterface</hardwareInterface>
      <mechanicalReduction>1</mechanicalReduction>
    </actuator>
  </transmission>
  <transmission name="m42_trans">
    <type>transmission_interface/SimpleTransmission</type>
    <joint name="m42">
      <hardwareInterface>hardware_interface/EffortJointInterface</hardwareInterface>
    </joint>
    <actuator name="m42_motor">
      <hardwareInterface>hardware_interface/EffortJointInterface</hardwareInterface>
      <mechanicalReduction>1</mechanicalReduction>
    </actuator>
  </transmission>
  <transmission name="m43_trans">
    <type>transmission_interface/SimpleTransmission</type>
    <joint name="m43">
      <hardwareInterface>hardware_interface/EffortJointInterface</hardwareInterface>
    </joint>
    <actuator name="m43_motor">
      <hardwareInterface>hardware_interface/EffortJointInterface</hardwareInterface>
      <mechanicalReduction>1</mechanicalReduction>
    </actuator>
  </transmission>
  <link name="5_coxa_link">
    <visual>
      <geometry>
        <mesh filename="package://hexapod/stl/coxa_l_link.stl"/>
      </geometry>
      <origin rpy="0 0 0" xyz="0 0 0"/>
      <material name="grey">
        <color rgba="0.67 0.67 0.67 1"/>
      </material>
    </visual>
    <inertial>
      <mass value="0.2"/>
      <inertia ixx="4.99231E-05" ixy="7.69231E-08" ixz="0" iyy="4.83846E-05" iyz="0" izz="4.83846E-05"/>
    </inertial>
    <collision>
      <geometry>
        <mesh filename="package://hexapod/stl/coxa_l_link.stl"/>
      </geometry>
      <origin rpy="0 0 0" xyz="0 0 0"/>
    </collision>
  </link>
  <joint name="m51" type="revolute">
    <parent link="hexapod_link"/>
    <child link="5_coxa_link"/>
    <origin rpy="0 0 3.489" xyz="-0.051 -0.217 0.0"/>
    <axis xyz="0 0 1"/>
    <limit effort="1000.0" lower="-0.548" upper="0.548" velocity="0.5"/>
  </joint>
  <link name="5_femur_link">
    <visual>
      <geometry>
        <mesh filename="package://hexapod/stl/femur_link.stl"/>
      </geometry>
      <origin rpy="0 0 0" xyz="0 0 0"/>
      <material name="grey">
        <color rgba="0.67 0.67 0.67 1"/>
      </material>
    </visual>
    <inertial>
      <mass value="0.2"/>
      <inertia ixx="2.40946E-05" ixy="-1.00676E-06" ixz="-7.43243E-07" iyy="0.000142824" iyz="-6.75676E-09" izz="0.000150466"/>
    </inertial>
    <collision>
      <geometry>
        <mesh filename="package://hexapod/stl/femur_link.stl"/>
      </geometry>
      <origin rpy="0 0 0" xyz="0 0 0"/>
    </collision>
  </link>
  <joint name="m52" type="revolute">
    <parent link="5_coxa_link"/>
    <child link="5_femur_link"/>
    <origin rpy="3.14 0 0" xyz="0.07 0.0 0.0"/>
    <axis xyz="0 1 0"/>
    <limit effort="1000.0" lower="-1.57" upper="1.57" velocity="0.5"/>
  </joint>
  <link name="5_tibia_link">
    <visual>
      <geometry>
        <mesh filename="package://hexapod/stl/tibia_link.stl"/>
      </geometry>
      <origin rpy="0 0 0" xyz="0 0 0"/>
      <material name="grey">
        <color rgba="0.67 0.67 0.67 1"/>
      </material>
    </visual>
    <inertial>
      <mass value="0.2"/>
      <inertia ixx="0.000296304" ixy="-4.34783E-08" ixz="3.26087E-06" iyy="0.000265391" iyz="1.73913E-06" izz="4.22174E-05"/>
    </inertial>
    <collision>
      <geometry>
        <mesh filename="package://hexapod/stl/tibia_link.stl"/>
      </geometry>
      <origin rpy="0 0 0" xyz="0 0 0"/>
    </collision>
  </link>
  <joint name="m53" type="revolute">
    <parent link="5_femur_link"/>
    <child link="5_tibia_link"/>
    <origin rpy="0 -1.57 0" xyz="0.096 0.0 0.0"/>
    <axis xyz="0 1 0"/>
    <limit effort="1000.0" lower="-1.57" upper="1.57" velocity="0.5"/>
  </joint>
  <link name="5_foot_link"/>
  <joint name="5_foot_joint" type="fixed">
    <parent link="5_tibia_link"/>
    <child link="5_foot_link"/>
    <origin rpy="0.0 0.0 0.0" xyz="0 0.0 -0.162"/>
    <axis xyz="0 1 0"/>
  </joint>
  <transmission name="m51_trans">
    <type>transmission_interface/SimpleTransmission</type>
    <joint name="m51">
      <hardwareInterface>hardware_interface/EffortJointInterface</hardwareInterface>
    </joint>
    <actuator name="m51_motor">
      <hardwareInterface>hardware_interface/EffortJointInterface</hardwareInterface>
      <mechanicalReduction>1</mechanicalReduction>
    </actuator>
  </transmission>
  <transmission name="m52_trans">
    <type>transmission_interface/SimpleTransmission</type>
    <joint name="m52">
      <hardwareInterface>hardware_interface/EffortJointInterface</hardwareInterface>
    </joint>
    <actuator name="m52_motor">
      <hardwareInterface>hardware_interface/EffortJointInterface</hardwareInterface>
      <mechanicalReduction>1</mechanicalReduction>
    </actuator>
  </transmission>
  <transmission name="m53_trans">
    <type>transmission_interface/SimpleTransmission</type>
    <joint name="m53">
      <hardwareInterface>hardware_interface/EffortJointInterface</hardwareInterface>
    </joint>
    <actuator name="m53_motor">
      <hardwareInterface>hardware_interface/EffortJointInterface</hardwareInterface>
      <mechanicalReduction>1</mechanicalReduction>
    </actuator>
  </transmission>
  <link name="6_coxa_link">
    <visual>
      <geometry>
        <mesh filename="package://hexapod/stl/coxa_r_link.stl"/>
      </geometry>
      <origin rpy="0 0 0" xyz="0 0 0"/>
      <material name="grey">
        <color rgba="0.67 0.67 0.67 1"/>
      </material>
    </visual>
    <inertial>
      <mass value="0.2"/>
      <inertia ixx="4.99231E-05" ixy="7.69231E-08" ixz="0" iyy="4.83846E-05" iyz="0" izz="4.83846E-05"/>
    </inertial>
    <collision>
      <geometry>
        <mesh filename="package://hexapod/stl/coxa_r_link.stl"/>
      </geometry>
      <origin rpy="0 0 0" xyz="0 0 0"/>
    </collision>
  </link>
  <joint name="m61" type="revolute">
    <parent link="hexapod_link"/>
    <child link="6_coxa_link"/>
    <origin rpy="0 0 2.791" xyz="0.051 -0.217 0.0"/>
    <axis xyz="0 0 1"/>
    <limit effort="1000.0" lower="-0.548" upper="0.548" velocity="0.5"/>
  </joint>
  <link name="6_femur_link">
    <visual>
      <geometry>
        <mesh filename="package://hexapod/stl/femur_link.stl"/>
      </geometry>
      <origin rpy="0 0 0" xyz="0 0 0"/>
      <material name="grey">
        <color rgba="0.67 0.67 0.67 1"/>
      </material>
    </visual>
    <inertial>
      <mass value="0.2"/>
      <inertia ixx="2.40946E-05" ixy="-1.00676E-06" ixz="-7.43243E-07" iyy="0.000142824" iyz="-6.75676E-09" izz="0.000150466"/>
    </inertial>
    <collision>
      <geometry>
        <mesh filename="package://hexapod/stl/femur_link.stl"/>
      </geometry>
      <origin rpy="0 0 0" xyz="0 0 0"/>
    </collision>
  </link>
  <joint name="m62" type="revolute">
    <parent link="6_coxa_link"/>
    <child link="6_femur_link"/>
    <origin rpy="0 3.14 0" xyz="-0.07 0.0 0.0"/>
    <axis xyz="0 1 0"/>
    <limit effort="1000.0" lower="-1.57" upper="1.57" velocity="0.5"/>
  </joint>
  <link name="6_tibia_link">
    <visual>
      <geometry>
        <mesh filename="package://hexapod/stl/tibia_link.stl"/>
      </geometry>
      <origin rpy="0 0 0" xyz="0 0 0"/>
      <material name="grey">
        <color rgba="0.67 0.67 0.67 1"/>
      </material>
    </visual>
    <inertial>
      <mass value="0.2"/>
      <inertia ixx="0.000296304" ixy="-4.34783E-08" ixz="3.26087E-06" iyy="0.000265391" iyz="1.73913E-06" izz="4.22174E-05"/>
    </inertial>
    <collision>
      <geometry>
        <mesh filename="package://hexapod/stl/tibia_link.stl"/>
      </geometry>
      <origin rpy="0 0 0" xyz="0 0 0"/>
    </collision>
  </link>
  <joint name="m63" type="revolute">
    <parent link="6_femur_link"/>
    <child link="6_tibia_link"/>
    <origin rpy="0 -1.57 0" xyz="0.096 0.0 0.0"/>
    <axis xyz="0 1 0"/>
    <limit effort="1000.0" lower="-1.57" upper="1.57" velocity="0.5"/>
  </joint>
  <link name="6_foot_link"/>
  <joint name="6_foot_joint" type="fixed">
    <parent link="6_tibia_link"/>
    <child link="6_foot_link"/>
    <origin rpy="0.0 0.0 0.0" xyz="0 0.0 -0.162"/>
    <axis xyz="0 1 0"/>
  </joint>
  <transmission name="m61_trans">
    <type>transmission_interface/SimpleTransmission</type>
    <joint name="m61">
      <hardwareInterface>hardware_interface/EffortJointInterface</hardwareInterface>
    </joint>
    <actuator name="m61_motor">
      <hardwareInterface>hardware_interface/EffortJointInterface</hardwareInterface>
      <mechanicalReduction>1</mechanicalReduction>
    </actuator>
  </transmission>
  <transmission name="m62_trans">
    <type>transmission_interface/SimpleTransmission</type>
    <joint name="m62">
      <hardwareInterface>hardware_interface/EffortJointInterface</hardwareInterface>
    </joint>
    <actuator name="m62_motor">
      <hardwareInterface>hardware_interface/EffortJointInterface</hardwareInterface>
      <mechanicalReduction>1</mechanicalReduction>
    </actuator>
  </transmission>
  <transmission name="m63_trans">
    <type>transmission_interface/SimpleTransmission</type>
    <joint name="m63">
      <hardwareInterface>hardware_interface/EffortJointInterface</hardwareInterface>
    </joint>
    <actuator name="m63_motor">
      <hardwareInterface>hardware_interface/EffortJointInterface</hardwareInterface>
      <mechanicalReduction>1</mechanicalReduction>
    </actuator>
  </transmission>
</robot>

